2020-12-31T00:06:46-0300 [stderr#error] Exception in Tkinter callback
2020-12-31T00:06:46-0300 [stderr#error] Traceback (most recent call last):
2020-12-31T00:06:46-0300 [stderr#error]   File "/usr/lib/python3.6/tkinter/__init__.py", line 1708, in __call__
2020-12-31T00:06:46-0300 [stderr#error]     return self.func(*args)
2020-12-31T00:06:46-0300 [stderr#error]   File "/home/rafael/iotfogsim/scinetsim/scinetsim/configurations.py", line 112, in <lambda>
2020-12-31T00:06:46-0300 [stderr#error]     btn_open = ttk.Button(window, text="Open Project",command=lambda:open_project(window,simulation_core))
2020-12-31T00:06:46-0300 [stderr#error]   File "/home/rafael/iotfogsim/scinetsim/scinetsim/configurations.py", line 63, in open_project
2020-12-31T00:06:46-0300 [stderr#error]     simulation_core.create_simulation_canvas()
2020-12-31T00:06:46-0300 [stderr#error]   File "/home/rafael/iotfogsim/scinetsim/scinetsim/simulationcore.py", line 198, in create_simulation_canvas
2020-12-31T00:06:46-0300 [stderr#error]     window.create_image(10, 10, image = image, anchor = 'nw')
2020-12-31T00:06:46-0300 [stderr#error] AttributeError: 'Toplevel' object has no attribute 'create_image'
2020-12-31T00:10:32-0300 [-] Received SIGINT, shutting down.
2020-12-31T00:10:32-0300 [-] Main loop terminated.
