2020-12-31T00:01:08-0300 [stderr#error] Exception in Tkinter callback
2020-12-31T00:01:08-0300 [stderr#error] Traceback (most recent call last):
2020-12-31T00:01:08-0300 [stderr#error]   File "/usr/lib/python3.6/tkinter/__init__.py", line 1708, in __call__
2020-12-31T00:01:08-0300 [stderr#error]     return self.func(*args)
2020-12-31T00:01:08-0300 [stderr#error]   File "/home/rafael/iotfogsim/scinetsim/scinetsim/configurations.py", line 112, in <lambda>
2020-12-31T00:01:08-0300 [stderr#error]     btn_open = ttk.Button(window, text="Open Project",command=lambda:open_project(window,simulation_core))
2020-12-31T00:01:08-0300 [stderr#error]   File "/home/rafael/iotfogsim/scinetsim/scinetsim/configurations.py", line 63, in open_project
2020-12-31T00:01:08-0300 [stderr#error]     simulation_core.create_simulation_canvas()
2020-12-31T00:01:08-0300 [stderr#error]   File "/home/rafael/iotfogsim/scinetsim/scinetsim/simulationcore.py", line 196, in create_simulation_canvas
2020-12-31T00:01:08-0300 [stderr#error]     self.simulation_screen = ScrollableScreen(window)
2020-12-31T00:01:08-0300 [stderr#error]   File "/home/rafael/iotfogsim/scinetsim/scinetsim/ScrollableScreen.py", line 33, in __init__
2020-12-31T00:01:08-0300 [stderr#error]     image = ImageTk.PhotoImage(file = "../teste.png")
2020-12-31T00:01:08-0300 [stderr#error]   File "/home/rafael/iotfogsim/vm/lib/python3.6/site-packages/PIL/ImageTk.py", line 95, in __init__
2020-12-31T00:01:08-0300 [stderr#error]     image = _get_image_from_kw(kw)
2020-12-31T00:01:08-0300 [stderr#error]   File "/home/rafael/iotfogsim/vm/lib/python3.6/site-packages/PIL/ImageTk.py", line 64, in _get_image_from_kw
2020-12-31T00:01:08-0300 [stderr#error]     return Image.open(source)
2020-12-31T00:01:08-0300 [stderr#error]   File "/home/rafael/iotfogsim/vm/lib/python3.6/site-packages/PIL/Image.py", line 2766, in open
2020-12-31T00:01:08-0300 [stderr#error]     fp = builtins.open(filename, "rb")
2020-12-31T00:01:08-0300 [stderr#error] FileNotFoundError: [Errno 2] No such file or directory: '../teste.png'
2020-12-31T00:02:05-0300 [-] Received SIGINT, shutting down.
2020-12-31T00:02:05-0300 [-] Main loop terminated.
2020-12-31T00:02:05-0300 [stderr#error] Exception ignored in: <bound method PhotoImage.__del__ of <PIL.ImageTk.PhotoImage object at 0x7fe30c323588>>
2020-12-31T00:02:05-0300 [stderr#error] Traceback (most recent call last):
2020-12-31T00:02:05-0300 [stderr#error]   File "/home/rafael/iotfogsim/vm/lib/python3.6/site-packages/PIL/ImageTk.py", line 124, in __del__
2020-12-31T00:02:05-0300 [stderr#error]     name = self.__photo.name
2020-12-31T00:02:05-0300 [stderr#error] AttributeError: 'PhotoImage' object has no attribute '_PhotoImage__photo'
