2020-02-26T09:39:21-0300 [-] Creating router ...
2020-02-26T09:39:21-0300 [-] Initializing Router - Number of events: 1
2020-02-26T09:39:21-0300 [-] RouterFactory starting on 8081
2020-02-26T09:39:21-0300 [-] Creating fog node ...
2020-02-26T09:39:21-0300 [stdout#info] applications.mqttapp.SubscriberApp
2020-02-26T09:39:21-0300 [-] Initializing Client - Number of events: 2
2020-02-26T09:39:21-0300 [-] Creating fog node ...
2020-02-26T09:39:21-0300 [-] Initializing Server - Number of events: 3
2020-02-26T09:39:21-0300 [-] BrokerFactory starting on 5100
2020-02-26T09:39:21-0300 [-] Creating iot node ...
2020-02-26T09:39:21-0300 [stdout#info] applications.mqttapp.PublisherApp
2020-02-26T09:39:21-0300 [-] Initializing Client - Number of events: 4
2020-02-26T09:39:21-0300 [-] Creating iot node ...
2020-02-26T09:39:21-0300 [stdout#info] applications.mqttapp.PublisherApp
2020-02-26T09:39:21-0300 [-] Initializing Client - Number of events: 5
2020-02-26T09:39:21-0300 [stdout#info] This divice have no simulation core instance
2020-02-26T09:39:21-0300 [stdout#info] This divice have no simulation core instance
2020-02-26T09:39:21-0300 [stdout#info] This divice have no simulation core instance
2020-02-26T09:39:21-0300 [stdout#info] This divice have no simulation core instance
2020-02-26T09:39:21-0300 [Uninitialized] 127.0.0.1:50644 - Connected to mqtt broker - Number of events: 6
2020-02-26T09:39:21-0300 [Uninitialized] 127.0.0.1:50644 - sending MQTT SUBSCRIBE REQUEST - Number of events: 7
2020-02-26T09:39:21-0300 [Uninitialized] 127.0.0.1:50646 - Connected to mqtt broker - Number of events: 8
2020-02-26T09:39:21-0300 [Uninitialized] 127.0.0.1:50646 - sending MQTT PUBLISH REQUEST - Number of events: 9
2020-02-26T09:39:21-0300 [Uninitialized] 127.0.0.1:50648 - Connected to mqtt broker - Number of events: 10
2020-02-26T09:39:21-0300 [Uninitialized] 127.0.0.1:50648 - sending MQTT PUBLISH REQUEST - Number of events: 11
2020-02-26T09:39:21-0300 [twisted.internet.endpoints.OneShotFactory#info] Starting factory <twisted.internet.endpoints.connectProtocol.<locals>.OneShotFactory object at 0x7f48e6e2eba8>
2020-02-26T09:39:21-0300 [twisted.internet.endpoints.OneShotFactory#info] Starting factory <twisted.internet.endpoints.connectProtocol.<locals>.OneShotFactory object at 0x7f48e6e2eda0>
2020-02-26T09:39:21-0300 [twisted.internet.endpoints.OneShotFactory#info] Starting factory <twisted.internet.endpoints.connectProtocol.<locals>.OneShotFactory object at 0x7f48e6e2ef98>
2020-02-26T09:39:26-0300 [-] 127.0.0.1:50646 - sending MQTT PUBLISH REQUEST - Number of events: 12
2020-02-26T09:39:26-0300 [-] 127.0.0.1:50648 - sending MQTT PUBLISH REQUEST - Number of events: 13
2020-02-26T09:39:26-0300 [twisted.internet.endpoints.OneShotFactory#info] Starting factory <twisted.internet.endpoints.connectProtocol.<locals>.OneShotFactory object at 0x7f48e6e42780>
2020-02-26T09:39:26-0300 [twisted.internet.endpoints.OneShotFactory#info] Starting factory <twisted.internet.endpoints.connectProtocol.<locals>.OneShotFactory object at 0x7f48e6e429b0>
2020-02-26T09:39:31-0300 [-] 127.0.0.1:50646 - sending MQTT PUBLISH REQUEST - Number of events: 14
2020-02-26T09:39:31-0300 [-] 127.0.0.1:50648 - sending MQTT PUBLISH REQUEST - Number of events: 15
2020-02-26T09:39:31-0300 [twisted.internet.endpoints.OneShotFactory#info] Starting factory <twisted.internet.endpoints.connectProtocol.<locals>.OneShotFactory object at 0x7f48e6e426d8>
2020-02-26T09:39:31-0300 [twisted.internet.endpoints.OneShotFactory#info] Starting factory <twisted.internet.endpoints.connectProtocol.<locals>.OneShotFactory object at 0x7f48e6e42f28>
2020-02-26T09:39:32-0300 [-] Received SIGINT, shutting down.
2020-02-26T09:39:32-0300 [applications.routerapp.RouterFactory] (TCP Port 8081 Closed)
2020-02-26T09:39:32-0300 [ClientProtocol,client] connection lost: Connection to the other side was lost in a non-clean fashion: Connection lost.
2020-02-26T09:39:32-0300 [ClientProtocol,client] connection lost - Number of events: 16
2020-02-26T09:39:32-0300 [twisted.internet.endpoints.OneShotFactory#info] Stopping factory <twisted.internet.endpoints.connectProtocol.<locals>.OneShotFactory object at 0x7f48e6e42f28>
2020-02-26T09:39:32-0300 [BrokerProtocol,3,127.0.0.1] Unhandled Error
	Traceback (most recent call last):
	  File "/home/rafael/iotfogsim/vm/lib/python3.6/site-packages/twisted/internet/defer.py", line 311, in addCallbacks
	    self._runCallbacks()
	  File "/home/rafael/iotfogsim/vm/lib/python3.6/site-packages/twisted/internet/defer.py", line 654, in _runCallbacks
	    current.result = callback(current.result, *args, **kw)
	  File "/home/rafael/iotfogsim/vm/lib/python3.6/site-packages/twisted/internet/base.py", line 447, in _continueFiring
	    callable(*args, **kwargs)
	  File "/home/rafael/iotfogsim/vm/lib/python3.6/site-packages/twisted/internet/base.py", line 706, in disconnectAll
	    failure.Failure(main.CONNECTION_LOST))
	--- <exception caught here> ---
	  File "/home/rafael/iotfogsim/vm/lib/python3.6/site-packages/twisted/python/log.py", line 103, in callWithLogger
	    return callWithContext({"system": lp}, func, *args, **kw)
	  File "/home/rafael/iotfogsim/vm/lib/python3.6/site-packages/twisted/python/log.py", line 86, in callWithContext
	    return context.call({ILogContext: newCtx}, func, *args, **kw)
	  File "/home/rafael/iotfogsim/vm/lib/python3.6/site-packages/twisted/python/context.py", line 122, in callWithContext
	    return self.currentContext().callWithContext(ctx, func, *args, **kw)
	  File "/home/rafael/iotfogsim/vm/lib/python3.6/site-packages/twisted/python/context.py", line 85, in callWithContext
	    return func(*args,**kw)
	  File "/home/rafael/iotfogsim/vm/lib/python3.6/site-packages/twisted/internet/tcp.py", line 327, in connectionLost
	    protocol.connectionLost(reason)
	  File "/home/rafael/iotfogsim/scinetsim/applications/mqttapp.py", line 153, in connectionLost
	    self.factory.subscribers.remove(self)
	builtins.KeyError: <applications.mqttapp.BrokerProtocol object at 0x7f48e6e42828>
	
2020-02-26T09:39:32-0300 [ClientProtocol,client] connection lost: Connection to the other side was lost in a non-clean fashion: Connection lost.
2020-02-26T09:39:32-0300 [ClientProtocol,client] Unhandled Error
	Traceback (most recent call last):
	  File "/home/rafael/iotfogsim/vm/lib/python3.6/site-packages/twisted/internet/defer.py", line 311, in addCallbacks
	    self._runCallbacks()
	  File "/home/rafael/iotfogsim/vm/lib/python3.6/site-packages/twisted/internet/defer.py", line 654, in _runCallbacks
	    current.result = callback(current.result, *args, **kw)
	  File "/home/rafael/iotfogsim/vm/lib/python3.6/site-packages/twisted/internet/base.py", line 447, in _continueFiring
	    callable(*args, **kwargs)
	  File "/home/rafael/iotfogsim/vm/lib/python3.6/site-packages/twisted/internet/base.py", line 706, in disconnectAll
	    failure.Failure(main.CONNECTION_LOST))
	--- <exception caught here> ---
	  File "/home/rafael/iotfogsim/vm/lib/python3.6/site-packages/twisted/python/log.py", line 103, in callWithLogger
	    return callWithContext({"system": lp}, func, *args, **kw)
	  File "/home/rafael/iotfogsim/vm/lib/python3.6/site-packages/twisted/python/log.py", line 86, in callWithContext
	    return context.call({ILogContext: newCtx}, func, *args, **kw)
	  File "/home/rafael/iotfogsim/vm/lib/python3.6/site-packages/twisted/python/context.py", line 122, in callWithContext
	    return self.currentContext().callWithContext(ctx, func, *args, **kw)
	  File "/home/rafael/iotfogsim/vm/lib/python3.6/site-packages/twisted/python/context.py", line 85, in callWithContext
	    return func(*args,**kw)
	  File "/home/rafael/iotfogsim/vm/lib/python3.6/site-packages/twisted/internet/tcp.py", line 519, in connectionLost
	    self._commonConnection.connectionLost(self, reason)
	  File "/home/rafael/iotfogsim/vm/lib/python3.6/site-packages/twisted/internet/tcp.py", line 327, in connectionLost
	    protocol.connectionLost(reason)
	  File "/home/rafael/iotfogsim/vm/lib/python3.6/site-packages/twisted/internet/endpoints.py", line 146, in connectionLost
	    return self._wrappedProtocol.connectionLost(reason)
	  File "/home/rafael/iotfogsim/scinetsim/applications/applicationcomponent.py", line 55, in connectionLost
	    self.simulation_core.updateEventsCounter("connection lost")
	builtins.AttributeError: 'NoneType' object has no attribute 'updateEventsCounter'
	
2020-02-26T09:39:32-0300 [RouterAppProtocol,2,127.0.0.1] connection lost: Connection to the other side was lost in a non-clean fashion: Connection lost.
2020-02-26T09:39:32-0300 [RouterAppProtocol,2,127.0.0.1] Unhandled Error
	Traceback (most recent call last):
	  File "/home/rafael/iotfogsim/vm/lib/python3.6/site-packages/twisted/internet/defer.py", line 311, in addCallbacks
	    self._runCallbacks()
	  File "/home/rafael/iotfogsim/vm/lib/python3.6/site-packages/twisted/internet/defer.py", line 654, in _runCallbacks
	    current.result = callback(current.result, *args, **kw)
	  File "/home/rafael/iotfogsim/vm/lib/python3.6/site-packages/twisted/internet/base.py", line 447, in _continueFiring
	    callable(*args, **kwargs)
	  File "/home/rafael/iotfogsim/vm/lib/python3.6/site-packages/twisted/internet/base.py", line 706, in disconnectAll
	    failure.Failure(main.CONNECTION_LOST))
	--- <exception caught here> ---
	  File "/home/rafael/iotfogsim/vm/lib/python3.6/site-packages/twisted/python/log.py", line 103, in callWithLogger
	    return callWithContext({"system": lp}, func, *args, **kw)
	  File "/home/rafael/iotfogsim/vm/lib/python3.6/site-packages/twisted/python/log.py", line 86, in callWithContext
	    return context.call({ILogContext: newCtx}, func, *args, **kw)
	  File "/home/rafael/iotfogsim/vm/lib/python3.6/site-packages/twisted/python/context.py", line 122, in callWithContext
	    return self.currentContext().callWithContext(ctx, func, *args, **kw)
	  File "/home/rafael/iotfogsim/vm/lib/python3.6/site-packages/twisted/python/context.py", line 85, in callWithContext
	    return func(*args,**kw)
	  File "/home/rafael/iotfogsim/vm/lib/python3.6/site-packages/twisted/internet/tcp.py", line 327, in connectionLost
	    protocol.connectionLost(reason)
	  File "/home/rafael/iotfogsim/scinetsim/applications/applicationcomponent.py", line 55, in connectionLost
	    self.simulation_core.updateEventsCounter("connection lost")
	builtins.AttributeError: 'NoneType' object has no attribute 'updateEventsCounter'
	
2020-02-26T09:39:32-0300 [ClientProtocol,client] connection lost: Connection to the other side was lost in a non-clean fashion: Connection lost.
2020-02-26T09:39:32-0300 [ClientProtocol,client] connection lost - Number of events: 17
2020-02-26T09:39:32-0300 [twisted.internet.endpoints.OneShotFactory#info] Stopping factory <twisted.internet.endpoints.connectProtocol.<locals>.OneShotFactory object at 0x7f48e6e2ef98>
2020-02-26T09:39:32-0300 [BrokerProtocol,6,127.0.0.1] Unhandled Error
	Traceback (most recent call last):
	  File "/home/rafael/iotfogsim/vm/lib/python3.6/site-packages/twisted/internet/defer.py", line 311, in addCallbacks
	    self._runCallbacks()
	  File "/home/rafael/iotfogsim/vm/lib/python3.6/site-packages/twisted/internet/defer.py", line 654, in _runCallbacks
	    current.result = callback(current.result, *args, **kw)
	  File "/home/rafael/iotfogsim/vm/lib/python3.6/site-packages/twisted/internet/base.py", line 447, in _continueFiring
	    callable(*args, **kwargs)
	  File "/home/rafael/iotfogsim/vm/lib/python3.6/site-packages/twisted/internet/base.py", line 706, in disconnectAll
	    failure.Failure(main.CONNECTION_LOST))
	--- <exception caught here> ---
	  File "/home/rafael/iotfogsim/vm/lib/python3.6/site-packages/twisted/python/log.py", line 103, in callWithLogger
	    return callWithContext({"system": lp}, func, *args, **kw)
	  File "/home/rafael/iotfogsim/vm/lib/python3.6/site-packages/twisted/python/log.py", line 86, in callWithContext
	    return context.call({ILogContext: newCtx}, func, *args, **kw)
	  File "/home/rafael/iotfogsim/vm/lib/python3.6/site-packages/twisted/python/context.py", line 122, in callWithContext
	    return self.currentContext().callWithContext(ctx, func, *args, **kw)
	  File "/home/rafael/iotfogsim/vm/lib/python3.6/site-packages/twisted/python/context.py", line 85, in callWithContext
	    return func(*args,**kw)
	  File "/home/rafael/iotfogsim/vm/lib/python3.6/site-packages/twisted/internet/tcp.py", line 327, in connectionLost
	    protocol.connectionLost(reason)
	  File "/home/rafael/iotfogsim/scinetsim/applications/mqttapp.py", line 153, in connectionLost
	    self.factory.subscribers.remove(self)
	builtins.KeyError: <applications.mqttapp.BrokerProtocol object at 0x7f48e6e4c080>
	
2020-02-26T09:39:32-0300 [RouterAppProtocol,3,127.0.0.1] connection lost: Connection to the other side was lost in a non-clean fashion: Connection lost.
2020-02-26T09:39:32-0300 [RouterAppProtocol,3,127.0.0.1] connection lost - Number of events: 18
2020-02-26T09:39:32-0300 [RouterAppProtocol,0,127.0.0.1] connection lost: Connection to the other side was lost in a non-clean fashion: Connection lost.
2020-02-26T09:39:32-0300 [RouterAppProtocol,0,127.0.0.1] Unhandled Error
	Traceback (most recent call last):
	  File "/home/rafael/iotfogsim/vm/lib/python3.6/site-packages/twisted/internet/defer.py", line 311, in addCallbacks
	    self._runCallbacks()
	  File "/home/rafael/iotfogsim/vm/lib/python3.6/site-packages/twisted/internet/defer.py", line 654, in _runCallbacks
	    current.result = callback(current.result, *args, **kw)
	  File "/home/rafael/iotfogsim/vm/lib/python3.6/site-packages/twisted/internet/base.py", line 447, in _continueFiring
	    callable(*args, **kwargs)
	  File "/home/rafael/iotfogsim/vm/lib/python3.6/site-packages/twisted/internet/base.py", line 706, in disconnectAll
	    failure.Failure(main.CONNECTION_LOST))
	--- <exception caught here> ---
	  File "/home/rafael/iotfogsim/vm/lib/python3.6/site-packages/twisted/python/log.py", line 103, in callWithLogger
	    return callWithContext({"system": lp}, func, *args, **kw)
	  File "/home/rafael/iotfogsim/vm/lib/python3.6/site-packages/twisted/python/log.py", line 86, in callWithContext
	    return context.call({ILogContext: newCtx}, func, *args, **kw)
	  File "/home/rafael/iotfogsim/vm/lib/python3.6/site-packages/twisted/python/context.py", line 122, in callWithContext
	    return self.currentContext().callWithContext(ctx, func, *args, **kw)
	  File "/home/rafael/iotfogsim/vm/lib/python3.6/site-packages/twisted/python/context.py", line 85, in callWithContext
	    return func(*args,**kw)
	  File "/home/rafael/iotfogsim/vm/lib/python3.6/site-packages/twisted/internet/tcp.py", line 327, in connectionLost
	    protocol.connectionLost(reason)
	  File "/home/rafael/iotfogsim/scinetsim/applications/applicationcomponent.py", line 55, in connectionLost
	    self.simulation_core.updateEventsCounter("connection lost")
	builtins.AttributeError: 'NoneType' object has no attribute 'updateEventsCounter'
	
2020-02-26T09:39:32-0300 [BrokerProtocol,5,127.0.0.1] Unhandled Error
	Traceback (most recent call last):
	  File "/home/rafael/iotfogsim/vm/lib/python3.6/site-packages/twisted/internet/defer.py", line 311, in addCallbacks
	    self._runCallbacks()
	  File "/home/rafael/iotfogsim/vm/lib/python3.6/site-packages/twisted/internet/defer.py", line 654, in _runCallbacks
	    current.result = callback(current.result, *args, **kw)
	  File "/home/rafael/iotfogsim/vm/lib/python3.6/site-packages/twisted/internet/base.py", line 447, in _continueFiring
	    callable(*args, **kwargs)
	  File "/home/rafael/iotfogsim/vm/lib/python3.6/site-packages/twisted/internet/base.py", line 706, in disconnectAll
	    failure.Failure(main.CONNECTION_LOST))
	--- <exception caught here> ---
	  File "/home/rafael/iotfogsim/vm/lib/python3.6/site-packages/twisted/python/log.py", line 103, in callWithLogger
	    return callWithContext({"system": lp}, func, *args, **kw)
	  File "/home/rafael/iotfogsim/vm/lib/python3.6/site-packages/twisted/python/log.py", line 86, in callWithContext
	    return context.call({ILogContext: newCtx}, func, *args, **kw)
	  File "/home/rafael/iotfogsim/vm/lib/python3.6/site-packages/twisted/python/context.py", line 122, in callWithContext
	    return self.currentContext().callWithContext(ctx, func, *args, **kw)
	  File "/home/rafael/iotfogsim/vm/lib/python3.6/site-packages/twisted/python/context.py", line 85, in callWithContext
	    return func(*args,**kw)
	  File "/home/rafael/iotfogsim/vm/lib/python3.6/site-packages/twisted/internet/tcp.py", line 327, in connectionLost
	    protocol.connectionLost(reason)
	  File "/home/rafael/iotfogsim/scinetsim/applications/mqttapp.py", line 153, in connectionLost
	    self.factory.subscribers.remove(self)
	builtins.KeyError: <applications.mqttapp.BrokerProtocol object at 0x7f48e6e42e10>
	
2020-02-26T09:39:32-0300 [SubscriberApp,client] connection lost: Connection to the other side was lost in a non-clean fashion: Connection lost.
2020-02-26T09:39:32-0300 [SubscriberApp,client] connection lost - Number of events: 19
2020-02-26T09:39:32-0300 [ClientProtocol,client] connection lost: Connection to the other side was lost in a non-clean fashion: Connection lost.
2020-02-26T09:39:32-0300 [ClientProtocol,client] Unhandled Error
	Traceback (most recent call last):
	  File "/home/rafael/iotfogsim/vm/lib/python3.6/site-packages/twisted/internet/defer.py", line 311, in addCallbacks
	    self._runCallbacks()
	  File "/home/rafael/iotfogsim/vm/lib/python3.6/site-packages/twisted/internet/defer.py", line 654, in _runCallbacks
	    current.result = callback(current.result, *args, **kw)
	  File "/home/rafael/iotfogsim/vm/lib/python3.6/site-packages/twisted/internet/base.py", line 447, in _continueFiring
	    callable(*args, **kwargs)
	  File "/home/rafael/iotfogsim/vm/lib/python3.6/site-packages/twisted/internet/base.py", line 706, in disconnectAll
	    failure.Failure(main.CONNECTION_LOST))
	--- <exception caught here> ---
	  File "/home/rafael/iotfogsim/vm/lib/python3.6/site-packages/twisted/python/log.py", line 103, in callWithLogger
	    return callWithContext({"system": lp}, func, *args, **kw)
	  File "/home/rafael/iotfogsim/vm/lib/python3.6/site-packages/twisted/python/log.py", line 86, in callWithContext
	    return context.call({ILogContext: newCtx}, func, *args, **kw)
	  File "/home/rafael/iotfogsim/vm/lib/python3.6/site-packages/twisted/python/context.py", line 122, in callWithContext
	    return self.currentContext().callWithContext(ctx, func, *args, **kw)
	  File "/home/rafael/iotfogsim/vm/lib/python3.6/site-packages/twisted/python/context.py", line 85, in callWithContext
	    return func(*args,**kw)
	  File "/home/rafael/iotfogsim/vm/lib/python3.6/site-packages/twisted/internet/tcp.py", line 519, in connectionLost
	    self._commonConnection.connectionLost(self, reason)
	  File "/home/rafael/iotfogsim/vm/lib/python3.6/site-packages/twisted/internet/tcp.py", line 327, in connectionLost
	    protocol.connectionLost(reason)
	  File "/home/rafael/iotfogsim/vm/lib/python3.6/site-packages/twisted/internet/endpoints.py", line 146, in connectionLost
	    return self._wrappedProtocol.connectionLost(reason)
	  File "/home/rafael/iotfogsim/scinetsim/applications/applicationcomponent.py", line 55, in connectionLost
	    self.simulation_core.updateEventsCounter("connection lost")
	builtins.AttributeError: 'NoneType' object has no attribute 'updateEventsCounter'
	
2020-02-26T09:39:32-0300 [applications.mqttapp.BrokerFactory] (TCP Port 5100 Closed)
2020-02-26T09:39:32-0300 [ClientProtocol,client] connection lost: Connection to the other side was lost in a non-clean fashion: Connection lost.
2020-02-26T09:39:32-0300 [ClientProtocol,client] Unhandled Error
	Traceback (most recent call last):
	  File "/home/rafael/iotfogsim/vm/lib/python3.6/site-packages/twisted/internet/defer.py", line 311, in addCallbacks
	    self._runCallbacks()
	  File "/home/rafael/iotfogsim/vm/lib/python3.6/site-packages/twisted/internet/defer.py", line 654, in _runCallbacks
	    current.result = callback(current.result, *args, **kw)
	  File "/home/rafael/iotfogsim/vm/lib/python3.6/site-packages/twisted/internet/base.py", line 447, in _continueFiring
	    callable(*args, **kwargs)
	  File "/home/rafael/iotfogsim/vm/lib/python3.6/site-packages/twisted/internet/base.py", line 706, in disconnectAll
	    failure.Failure(main.CONNECTION_LOST))
	--- <exception caught here> ---
	  File "/home/rafael/iotfogsim/vm/lib/python3.6/site-packages/twisted/python/log.py", line 103, in callWithLogger
	    return callWithContext({"system": lp}, func, *args, **kw)
	  File "/home/rafael/iotfogsim/vm/lib/python3.6/site-packages/twisted/python/log.py", line 86, in callWithContext
	    return context.call({ILogContext: newCtx}, func, *args, **kw)
	  File "/home/rafael/iotfogsim/vm/lib/python3.6/site-packages/twisted/python/context.py", line 122, in callWithContext
	    return self.currentContext().callWithContext(ctx, func, *args, **kw)
	  File "/home/rafael/iotfogsim/vm/lib/python3.6/site-packages/twisted/python/context.py", line 85, in callWithContext
	    return func(*args,**kw)
	  File "/home/rafael/iotfogsim/vm/lib/python3.6/site-packages/twisted/internet/tcp.py", line 519, in connectionLost
	    self._commonConnection.connectionLost(self, reason)
	  File "/home/rafael/iotfogsim/vm/lib/python3.6/site-packages/twisted/internet/tcp.py", line 327, in connectionLost
	    protocol.connectionLost(reason)
	  File "/home/rafael/iotfogsim/vm/lib/python3.6/site-packages/twisted/internet/endpoints.py", line 146, in connectionLost
	    return self._wrappedProtocol.connectionLost(reason)
	  File "/home/rafael/iotfogsim/scinetsim/applications/applicationcomponent.py", line 55, in connectionLost
	    self.simulation_core.updateEventsCounter("connection lost")
	builtins.AttributeError: 'NoneType' object has no attribute 'updateEventsCounter'
	
2020-02-26T09:39:32-0300 [ClientProtocol,client] connection lost: Connection to the other side was lost in a non-clean fashion: Connection lost.
2020-02-26T09:39:32-0300 [ClientProtocol,client] Unhandled Error
	Traceback (most recent call last):
	  File "/home/rafael/iotfogsim/vm/lib/python3.6/site-packages/twisted/internet/defer.py", line 311, in addCallbacks
	    self._runCallbacks()
	  File "/home/rafael/iotfogsim/vm/lib/python3.6/site-packages/twisted/internet/defer.py", line 654, in _runCallbacks
	    current.result = callback(current.result, *args, **kw)
	  File "/home/rafael/iotfogsim/vm/lib/python3.6/site-packages/twisted/internet/base.py", line 447, in _continueFiring
	    callable(*args, **kwargs)
	  File "/home/rafael/iotfogsim/vm/lib/python3.6/site-packages/twisted/internet/base.py", line 706, in disconnectAll
	    failure.Failure(main.CONNECTION_LOST))
	--- <exception caught here> ---
	  File "/home/rafael/iotfogsim/vm/lib/python3.6/site-packages/twisted/python/log.py", line 103, in callWithLogger
	    return callWithContext({"system": lp}, func, *args, **kw)
	  File "/home/rafael/iotfogsim/vm/lib/python3.6/site-packages/twisted/python/log.py", line 86, in callWithContext
	    return context.call({ILogContext: newCtx}, func, *args, **kw)
	  File "/home/rafael/iotfogsim/vm/lib/python3.6/site-packages/twisted/python/context.py", line 122, in callWithContext
	    return self.currentContext().callWithContext(ctx, func, *args, **kw)
	  File "/home/rafael/iotfogsim/vm/lib/python3.6/site-packages/twisted/python/context.py", line 85, in callWithContext
	    return func(*args,**kw)
	  File "/home/rafael/iotfogsim/vm/lib/python3.6/site-packages/twisted/internet/tcp.py", line 519, in connectionLost
	    self._commonConnection.connectionLost(self, reason)
	  File "/home/rafael/iotfogsim/vm/lib/python3.6/site-packages/twisted/internet/tcp.py", line 327, in connectionLost
	    protocol.connectionLost(reason)
	  File "/home/rafael/iotfogsim/vm/lib/python3.6/site-packages/twisted/internet/endpoints.py", line 146, in connectionLost
	    return self._wrappedProtocol.connectionLost(reason)
	  File "/home/rafael/iotfogsim/scinetsim/applications/applicationcomponent.py", line 55, in connectionLost
	    self.simulation_core.updateEventsCounter("connection lost")
	builtins.AttributeError: 'NoneType' object has no attribute 'updateEventsCounter'
	
2020-02-26T09:39:32-0300 [ClientProtocol,client] connection lost: Connection to the other side was lost in a non-clean fashion: Connection lost.
2020-02-26T09:39:32-0300 [ClientProtocol,client] connection lost - Number of events: 20
2020-02-26T09:39:32-0300 [twisted.internet.endpoints.OneShotFactory#info] Stopping factory <twisted.internet.endpoints.connectProtocol.<locals>.OneShotFactory object at 0x7f48e6e429b0>
2020-02-26T09:39:32-0300 [PublisherApp,client] connection lost: Connection to the other side was lost in a non-clean fashion: Connection lost.
2020-02-26T09:39:32-0300 [PublisherApp,client] connection lost - Number of events: 21
2020-02-26T09:39:32-0300 [PublisherApp,client] connection lost: Connection to the other side was lost in a non-clean fashion: Connection lost.
2020-02-26T09:39:32-0300 [PublisherApp,client] connection lost - Number of events: 22
2020-02-26T09:39:32-0300 [BrokerProtocol,1,127.0.0.1] Unhandled Error
	Traceback (most recent call last):
	  File "/home/rafael/iotfogsim/vm/lib/python3.6/site-packages/twisted/internet/defer.py", line 311, in addCallbacks
	    self._runCallbacks()
	  File "/home/rafael/iotfogsim/vm/lib/python3.6/site-packages/twisted/internet/defer.py", line 654, in _runCallbacks
	    current.result = callback(current.result, *args, **kw)
	  File "/home/rafael/iotfogsim/vm/lib/python3.6/site-packages/twisted/internet/base.py", line 447, in _continueFiring
	    callable(*args, **kwargs)
	  File "/home/rafael/iotfogsim/vm/lib/python3.6/site-packages/twisted/internet/base.py", line 706, in disconnectAll
	    failure.Failure(main.CONNECTION_LOST))
	--- <exception caught here> ---
	  File "/home/rafael/iotfogsim/vm/lib/python3.6/site-packages/twisted/python/log.py", line 103, in callWithLogger
	    return callWithContext({"system": lp}, func, *args, **kw)
	  File "/home/rafael/iotfogsim/vm/lib/python3.6/site-packages/twisted/python/log.py", line 86, in callWithContext
	    return context.call({ILogContext: newCtx}, func, *args, **kw)
	  File "/home/rafael/iotfogsim/vm/lib/python3.6/site-packages/twisted/python/context.py", line 122, in callWithContext
	    return self.currentContext().callWithContext(ctx, func, *args, **kw)
	  File "/home/rafael/iotfogsim/vm/lib/python3.6/site-packages/twisted/python/context.py", line 85, in callWithContext
	    return func(*args,**kw)
	  File "/home/rafael/iotfogsim/vm/lib/python3.6/site-packages/twisted/internet/tcp.py", line 327, in connectionLost
	    protocol.connectionLost(reason)
	  File "/home/rafael/iotfogsim/scinetsim/applications/mqttapp.py", line 153, in connectionLost
	    self.factory.subscribers.remove(self)
	builtins.KeyError: <applications.mqttapp.BrokerProtocol object at 0x7f48e6e42358>
	
2020-02-26T09:39:32-0300 [RouterAppProtocol,1,127.0.0.1] connection lost: Connection to the other side was lost in a non-clean fashion: Connection lost.
2020-02-26T09:39:32-0300 [RouterAppProtocol,1,127.0.0.1] Unhandled Error
	Traceback (most recent call last):
	  File "/home/rafael/iotfogsim/vm/lib/python3.6/site-packages/twisted/internet/defer.py", line 311, in addCallbacks
	    self._runCallbacks()
	  File "/home/rafael/iotfogsim/vm/lib/python3.6/site-packages/twisted/internet/defer.py", line 654, in _runCallbacks
	    current.result = callback(current.result, *args, **kw)
	  File "/home/rafael/iotfogsim/vm/lib/python3.6/site-packages/twisted/internet/base.py", line 447, in _continueFiring
	    callable(*args, **kwargs)
	  File "/home/rafael/iotfogsim/vm/lib/python3.6/site-packages/twisted/internet/base.py", line 706, in disconnectAll
	    failure.Failure(main.CONNECTION_LOST))
	--- <exception caught here> ---
	  File "/home/rafael/iotfogsim/vm/lib/python3.6/site-packages/twisted/python/log.py", line 103, in callWithLogger
	    return callWithContext({"system": lp}, func, *args, **kw)
	  File "/home/rafael/iotfogsim/vm/lib/python3.6/site-packages/twisted/python/log.py", line 86, in callWithContext
	    return context.call({ILogContext: newCtx}, func, *args, **kw)
	  File "/home/rafael/iotfogsim/vm/lib/python3.6/site-packages/twisted/python/context.py", line 122, in callWithContext
	    return self.currentContext().callWithContext(ctx, func, *args, **kw)
	  File "/home/rafael/iotfogsim/vm/lib/python3.6/site-packages/twisted/python/context.py", line 85, in callWithContext
	    return func(*args,**kw)
	  File "/home/rafael/iotfogsim/vm/lib/python3.6/site-packages/twisted/internet/tcp.py", line 327, in connectionLost
	    protocol.connectionLost(reason)
	  File "/home/rafael/iotfogsim/scinetsim/applications/applicationcomponent.py", line 55, in connectionLost
	    self.simulation_core.updateEventsCounter("connection lost")
	builtins.AttributeError: 'NoneType' object has no attribute 'updateEventsCounter'
	
2020-02-26T09:39:32-0300 [BrokerProtocol,4,127.0.0.1] Unhandled Error
	Traceback (most recent call last):
	  File "/home/rafael/iotfogsim/vm/lib/python3.6/site-packages/twisted/internet/defer.py", line 311, in addCallbacks
	    self._runCallbacks()
	  File "/home/rafael/iotfogsim/vm/lib/python3.6/site-packages/twisted/internet/defer.py", line 654, in _runCallbacks
	    current.result = callback(current.result, *args, **kw)
	  File "/home/rafael/iotfogsim/vm/lib/python3.6/site-packages/twisted/internet/base.py", line 447, in _continueFiring
	    callable(*args, **kwargs)
	  File "/home/rafael/iotfogsim/vm/lib/python3.6/site-packages/twisted/internet/base.py", line 706, in disconnectAll
	    failure.Failure(main.CONNECTION_LOST))
	--- <exception caught here> ---
	  File "/home/rafael/iotfogsim/vm/lib/python3.6/site-packages/twisted/python/log.py", line 103, in callWithLogger
	    return callWithContext({"system": lp}, func, *args, **kw)
	  File "/home/rafael/iotfogsim/vm/lib/python3.6/site-packages/twisted/python/log.py", line 86, in callWithContext
	    return context.call({ILogContext: newCtx}, func, *args, **kw)
	  File "/home/rafael/iotfogsim/vm/lib/python3.6/site-packages/twisted/python/context.py", line 122, in callWithContext
	    return self.currentContext().callWithContext(ctx, func, *args, **kw)
	  File "/home/rafael/iotfogsim/vm/lib/python3.6/site-packages/twisted/python/context.py", line 85, in callWithContext
	    return func(*args,**kw)
	  File "/home/rafael/iotfogsim/vm/lib/python3.6/site-packages/twisted/internet/tcp.py", line 327, in connectionLost
	    protocol.connectionLost(reason)
	  File "/home/rafael/iotfogsim/scinetsim/applications/mqttapp.py", line 153, in connectionLost
	    self.factory.subscribers.remove(self)
	builtins.KeyError: <applications.mqttapp.BrokerProtocol object at 0x7f48e6e42b38>
	
2020-02-26T09:39:32-0300 [BrokerProtocol,2,127.0.0.1] Unhandled Error
	Traceback (most recent call last):
	  File "/home/rafael/iotfogsim/vm/lib/python3.6/site-packages/twisted/internet/defer.py", line 311, in addCallbacks
	    self._runCallbacks()
	  File "/home/rafael/iotfogsim/vm/lib/python3.6/site-packages/twisted/internet/defer.py", line 654, in _runCallbacks
	    current.result = callback(current.result, *args, **kw)
	  File "/home/rafael/iotfogsim/vm/lib/python3.6/site-packages/twisted/internet/base.py", line 447, in _continueFiring
	    callable(*args, **kwargs)
	  File "/home/rafael/iotfogsim/vm/lib/python3.6/site-packages/twisted/internet/base.py", line 706, in disconnectAll
	    failure.Failure(main.CONNECTION_LOST))
	--- <exception caught here> ---
	  File "/home/rafael/iotfogsim/vm/lib/python3.6/site-packages/twisted/python/log.py", line 103, in callWithLogger
	    return callWithContext({"system": lp}, func, *args, **kw)
	  File "/home/rafael/iotfogsim/vm/lib/python3.6/site-packages/twisted/python/log.py", line 86, in callWithContext
	    return context.call({ILogContext: newCtx}, func, *args, **kw)
	  File "/home/rafael/iotfogsim/vm/lib/python3.6/site-packages/twisted/python/context.py", line 122, in callWithContext
	    return self.currentContext().callWithContext(ctx, func, *args, **kw)
	  File "/home/rafael/iotfogsim/vm/lib/python3.6/site-packages/twisted/python/context.py", line 85, in callWithContext
	    return func(*args,**kw)
	  File "/home/rafael/iotfogsim/vm/lib/python3.6/site-packages/twisted/internet/tcp.py", line 327, in connectionLost
	    protocol.connectionLost(reason)
	  File "/home/rafael/iotfogsim/scinetsim/applications/mqttapp.py", line 153, in connectionLost
	    self.factory.subscribers.remove(self)
	builtins.KeyError: <applications.mqttapp.BrokerProtocol object at 0x7f48e6e422b0>
	
2020-02-26T09:39:32-0300 [-] Main loop terminated.
